Workbook

Sheet CARTERA
A1: Columna2 | B1: Columna1

Sheet Pedidos
A1: Esatdo Cartera | B1: ESTADO | C1: ID | D1: id_dropi | E1: fecha | F1: cliente | G1: transportadora | H1: estado_actualizado desde_app | I1: Estado de guia app (TEMP) | J1: estado_operativo | K1: guia | L1: despartamento | M1: ciudad | N1: direccion | O1: telefono | P1: Notas Manuales | Q1: notas | R1: Producto | S1: ganancia_calc | T1: costo_devolucion_estimado | U1: cartera | V1: cartera_aplicada | W1: venta | X1: flete | Y1: costo_proveedor | Z1: fecha_ult_mov | AA1: dias_desde_ult_mov | AB1: hora_ult_mov | AC1: ultimo_mov | AD1: estatus_original | AE1: estado_unificado
C2: 1062 | D2: 63461707 | E2: 46044 | F2: Gloria Del valle | G2: ENVIA | J2: PENDIENTE | L2: BOLIVAR | M2: CARTAGENA | N2: calle 5 #80e-45, barrio San Fernando | O2: 3243934970 | P2: {=IFERROR(_xlfn.XLOOKUP(tblPedidos[[#This Row],[id_dropi]],tblNotas[[#This Row],[id__dropi]],tblNotas[[#This Row],[Notas Manuales]], “”, 0),"")} | R2: Cepillo Plancha Secador 2 en 1 Alisador x1 | S2: 25511.5 | T2: -11990.8 | U2: {=IFERROR(_xlfn.IFS(tblPedidos[[#This Row],[estado_operativo]]="ENTREGADO",tblPedidos[[#This Row],[ganancia_calc]],tblPedidos[[#This Row],[estado_operativo]]="DEVOLUCION",tblPedidos[[#This Row],[costo_devolucion_estimado]]),0)} -> 0 | V2: 0 | W2: 54900 | X2: 14988.5 | Y2: 14400 | Z2: 46044 | AA2: 0 | AB2: 0.0020833333 | AC2: PENDIENTE | AD2: PENDIENTE | AE2: PENDIENTE
C3: 1061 | D3: 63461674 | E3: 46044 | F3: Nataly Montero Vquero | G3: INTERRAPIDISIMO | J3: PENDIENTE | L3: CUNDINAMARCA | M3: GUADUAS | N3: Cliente recoge pedido en oficina de Interrapidisimo en Guaduas cliente recoge en esa oficina | O3: 3142074177 | P3: {=IFERROR(_xlfn.XLOOKUP(tblPedidos[[#This Row],[id_dropi]],tblNotas[[#This Row],[id__dropi]],tblNotas[[#This Row],[Notas Manuales]], “”, 0),"")} | Q3: PEDIDO PARA RECOGER EN OFICINA DE INTERRAPIDISIMO | R3: Cepillo Plancha Secador 2 en 1 Alisador x2 | S3: 32079.5 | T3: -14020.5 | U3: {=IFERROR(_xlfn.IFS(tblPedidos[[#This Row],[estado_operativo]]="ENTREGADO",tblPedidos[[#This Row],[ganancia_calc]],tblPedidos[[#This Row],[estado_operativo]]="DEVOLUCION",tblPedidos[[#This Row],[costo_devolucion_estimado]]),0)} -> 0 | V3: 0 | W3: 74900 | X3: 14020.5 | Y3: 28800 | Z3: 46044 | AA3: 0 | AB3: 0.0020833333 | AC3: PENDIENTE | AD3: PENDIENTE | AE3: PENDIENTE
C4: 1064 | D4: 63461638 | E4: 46044 | F4: OrdaliZ Guzmán | G4: INTERRAPIDISIMO | J4: PENDIENTE | L4: ANTIOQUIA | M4: APARTADO | N4: Cliente recoge pedido en oficina de Interrapidisimo en Apartado cliente recoge en esa oficina | O4: 3108451453 | P4: {=IFERROR(_xlfn.XLOOKUP(tblPedidos[[#This Row],[id_dropi]],tblNotas[[#This Row],[id__dropi]],tblNotas[[#This Row],[Notas Manuales]], “”, 0),"")} | Q4: PEDIDO PARA RECOGER EN OFICINA DE INTERRAPIDISIMO | R4: Quemador de grasa Lemme Burn 60 cáps x2 | S4: 20654.5 | T4: -19245.5 | U4: {=IFERROR(_xlfn.IFS(tblPedidos[[#This Row],[estado_operativo]]="ENTREGADO",tblPedidos[[#This Row],[ganancia_calc]],tblPedidos[[#This Row],[estado_operativo]]="DEVOLUCION",tblPedidos[[#This Row],[costo_devolucion_estimado]]),0)} -> 0 | V4: 0 | W4: 89900 | X4: 19245.5 | Y4: 50000 | Z4: 46044 | AA4: 0 | AB4: 0.0013888889 | AC4: PENDIENTE | AD4: PENDIENTE | AE4: PENDIENTE
C5: 1063 | D5: 63461582 | E5: 46044 | F5: Rosalbina perdomo | G5: INTERRAPIDISIMO | J5: PENDIENTE | L5: CAQUETA | M5: FLORENCIA | N5: Calle 14 # 15 -68 barrio centro | O5: 3235021099 | P5: {=IFERROR(_xlfn.XLOOKUP(tblPedidos[[#This Row],[id_dropi]],tblNotas[[#This Row],[id__dropi]],tblNotas[[#This Row],[Notas Manuales]], “”, 0),"")} | R5: Bee Venom BSWELL x1 + Beevana crema +Varicose veins x1 | S5: 17004.5 | T5: -17895.5 | U5: {=IFERROR(_xlfn.IFS(tblPedidos[[#This Row],[estado_operativo]]="ENTREGADO",tblPedidos[[#This Row],[ganancia_calc]],tblPedidos[[#This Row],[estado_operativo]]="DEVOLUCION",tblPedidos[[#This Row],[costo_devolucion_estimado]]),0)} -> 0 | V5: 0 | W5: 59900 | X5: 17895.5 | Y5: 25000 | Z5: 46044 | AA5: 0 | AB5: 0 | AC5: PENDIENTE | AD5: PENDIENTE | AE5: PENDIENTE
C6: 1022 | D6: 63461491 | E6: 46043 | F6: Gloria Janeth Vanegas Mendoza | G6: INTERRAPIDISIMO | J6: PENDIENTE | L6: QUINDIO | M6: ARMENIA (Q) | N6: Barrio los arcades manzana K número 20 | O6: 3133277752 | P6: {=IFERROR(_xlfn.XLOOKUP(tblPedidos[[#This Row],[id_dropi]],tblNotas[[#This Row],[id__dropi]],tblNotas[[#This Row],[Notas Manuales]], “”, 0),"")} | R6: Bee Venom BSWELL x1 + Beevana crema +Varicose veins x1 | S6: 17004.5 | T6: -17895.5 | U6: {=IFERROR(_xlfn.IFS(tblPedidos[[#This Row],[estado_operativo]]="ENTREGADO",tblPedidos[[#This Row],[ganancia_calc]],tblPedidos[[#This Row],[estado_operativo]]="DEVOLUCION",tblPedidos[[#This Row],[costo_devolucion_estimado]]),0)} -> 0 | V6: 0 | W6: 59900 | X6: 17895.5 | Y6: 25000 | Z6: 46043 | AA6: 1 | AB6: 0.99861111 | AC6: PENDIENTE | AD6: PENDIENTE | AE6: PENDIENTE
C7: 1023 | D7: 63457261 | E7: 46043 | F7: Alexandra Hernández | G7: INTERRAPIDISIMO | J7: PENDIENTE | L7: CESAR | M7: LA LOMA | N7: La loma el paso, cesar. CR 13 # 16-05 | O7: 3126235411 | P7: {=IFERROR(_xlfn.XLOOKUP(tblPedidos[[#This Row],[id_dropi]],tblNotas[[#This Row],[id__dropi]],tblNotas[[#This Row],[Notas Manuales]], “”, 0),"")} | Q7: La loma el paso, cesar. CR 13 # 16 - 05. Barrio San Marcos. | R7: Cepillo Plancha Secador 2 en 1 Alisador x2 | S7: 27529.5 | T7: -18570.5 | U7: {=IFERROR(_xlfn.IFS(tblPedidos[[#This Row],[estado_operativo]]="ENTREGADO",tblPedidos[[#This Row],[ganancia_calc]],tblPedidos[[#This Row],[estado_operativo]]="DEVOLUCION",tblPedidos[[#This Row],[costo_devolucion_estimado]]),0)} -> 0 | V7: 0 | W7: 74900 | X7: 18570.5 | Y7: 28800 | Z7: 46043 | AA7: 1 | AB7: 0.95416667 | AC7: PENDIENTE | AD7: PENDIENTE | AE7: PENDIENTE
C8: 1024 | D8: 63457042 | E8: 46043 | F8: Herna Rivas | G8: ENVIA | J8: PENDIENTE | L8: VALLE | M8: BUGALAGRANDE | N8: Kr 5#3-84 Vuelta la virgen la María | O8: 3052542630 | P8: {=IFERROR(_xlfn.XLOOKUP(tblPedidos[[#This Row],[id_dropi]],tblNotas[[#This Row],[id__dropi]],tblNotas[[#This Row],[Notas Manuales]], “”, 0),"")} | Q8: Kr 5#3-84 Vuelta la virgen la María | R8: Cepillo Plancha Secador 2 en 1 Alisador x2 | S8: 25436.5 | T8: -12530.8 | U8: {=IFERROR(_xlfn.IFS(tblPedidos[[#This Row],[estado_operativo]]="ENTREGADO",tblPedidos[[#This Row],[ganancia_calc]],tblPedidos[[#This Row],[estado_operativo]]="DEVOLUCION",tblPedidos[[#This Row],[costo_devolucion_estimado]]),0)} -> 0 | V8: 0 | W8: 69900 | X8: 15663.5 | Y8: 28800 | Z8: 46043 | AA8: 1 | AB8: 0.95069444 | AC8: PENDIENTE | AD8: PENDIENTE | AE8: PENDIENTE
C9: 1021 | D9: 63456378 | E9: 46043 | F9: Miladys Arrieta | G9: INTERRAPIDISIMO | J9: PENDIENTE | L9: SUCRE | M9: SAN MARCOS | N9: OFICINA INTERRAPIDISIMO SAN MARCOS | O9: 3128625601 | P9: {=IFERROR(_xlfn.XLOOKUP(tblPedidos[[#This Row],[id_dropi]],tblNotas[[#This Row],[id__dropi]],tblNotas[[#This Row],[Notas Manuales]], “”, 0),"")} | Q9: CLIENTE RECLAMA EN OFICINA INTERRAPIDISIMO CARRERA 21 # 24A 44 SAN MARCOS SUCRE | R9: Cepillo Plancha Secador 2 en 1 Alisador x1 | S9: 16801 | T9: -18699 | U9: {=IFERROR(_xlfn.IFS(tblPedidos[[#This Row],[estado_operativo]]="ENTREGADO",tblPedidos[[#This Row],[ganancia_calc]],tblPedidos[[#This Row],[estado_operativo]]="DEVOLUCION",tblPedidos[[#This Row],[costo_devolucion_estimado]]),0)} -> 0 | V9: 0 | W9: 49900 | X9: 18699 | Y9: 14400 | Z9: 46043 | AA9: 1 | AB9: 0.94583333 | AC9: PENDIENTE | AD9: PENDIENTE | AE9: PENDIENTE
C10: 1018 | D10: 63455995 | E10: 46043 | F10: Yurany García | G10: INTERRAPIDISIMO | J10: PENDIENTE | L10: CUNDINAMARCA | M10: SOACHA | N10: OFICINA INTERRAPIDISIMO PRINCIPAL SOACHA | O10: 3214968096 | P10: {=IFERROR(_xlfn.XLOOKUP(tblPedidos[[#This Row],[id_dropi]],tblNotas[[#This Row],[id__dropi]],tblNotas[[#This Row],[Notas Manuales]], “”, 0),"")} | Q10: CLIENTE RECLAMA EN OFICINA INTERRAPIDISIMO PRINCIPAL SOACHA | R10: Cepillo Plancha Secador 2 en 1 Alisador x1 | S10: 28779.5 | T10: -11720.5 | U10: {=IFERROR(_xlfn.IFS(tblPedidos[[#This Row],[estado_operativo]]="ENTREGADO",tblPedidos[[#This Row],[ganancia_calc]],tblPedidos[[#This Row],[estado_operativo]]="DEVOLUCION",tblPedidos[[#This Row],[costo_devolucion_estimado]]),0)} -> 0 | V10: 0 | W10: 54900 | X10: 11720.5 | Y10: 14400 | Z10: 46043 | AA10: 1 | AB10: 0.94236111 | AC10: PENDIENTE | AD10: PENDIENTE | AE10: PENDIENTE
C11: 1019 | D11: 63455771 | E11: 46043 | F11: Mercedes Sepulveda | G11: INTERRAPIDISIMO | J11: PENDIENTE | L11: CUNDINAMARCA | M11: BOGOTA | N11: Calle 18 #4-51 | O11: 3125320701 | P11: {=IFERROR(_xlfn.XLOOKUP(tblPedidos[[#This Row],[id_dropi]],tblNotas[[#This Row],[id__dropi]],tblNotas[[#This Row],[Notas Manuales]], “”, 0),"")} | R11: Quemador de grasa Lemme Burn 60 cáps x2 | S11: 20654.5 | T11: -19245.5 | U11: {=IFERROR(_xlfn.IFS(tblPedidos[[#This Row],[estado_operativo]]="ENTREGADO",tblPedidos[[#This Row],[ganancia_calc]],tblPedidos[[#This Row],[estado_operativo]]="DEVOLUCION",tblPedidos[[#This Row],[costo_devolucion_estimado]]),0)} -> 0 | V11: 0 | W11: 89900 | X11: 19245.5 | Y11: 50000 | Z11: 46043 | AA11: 1 | AB11: 0.94097222 | AC11: PENDIENTE | AD11: PENDIENTE | AE11: PENDIENTE
C12: 1020 | D12: 63455714 | E12: 46043 | F12: Carmen Daniela Criollo Pacheco | G12: INTERRAPIDISIMO | J12: PENDIENTE | L12: ARAUCA | M12: SARAVENA | N12: Calle 7 #20-35 | O12: 3164638889 | P12: {=IFERROR(_xlfn.XLOOKUP(tblPedidos[[#This Row],[id_dropi]],tblNotas[[#This Row],[id__dropi]],tblNotas[[#This Row],[Notas Manuales]], “”, 0),"")} | R12: Cepillo Plancha Secador 2 en 1 Alisador x1 | S12: 16801 | T12: -18699 | U12: {=IFERROR(_xlfn.IFS(tblPedidos[[#This Row],[estado_operativo]]="ENTREGADO",tblPedidos[[#This Row],[ganancia_calc]],tblPedidos[[#This Row],[estado_operativo]]="DEVOLUCION",tblPedidos[[#This Row],[costo_devolucion_estimado]]),0)} -> 0 | V12: 0 | W12: 49900 | X12: 18699 | Y12: 14400 | Z12: 46043 | AA12: 1 | AB12: 0.94097222 | AC12: PENDIENTE | AD12: PENDIENTE | AE12: PENDIENTE
C13: 1029 | D13: 63455608 | E13: 46043 | F13: Nora Mosquera | G13: INTERRAPIDISIMO | J13: PENDIENTE | L13: CAUCA | M13: PUERTO TEJADA | N13: Cliente recoge pedido en oficina de Interrapidisimo en Puerto Tejada cliente recoge en esa oficina | O13: 3146569277 | P13: {=IFERROR(_xlfn.XLOOKUP(tblPedidos[[#This Row],[id_dropi]],tblNotas[[#This Row],[id__dropi]],tblNotas[[#This Row],[Notas Manuales]], “”, 0),"")} | Q13: PEDIDO PARA RECOGER EN OFICINA DE INTERRAPIDISIMO | R13: Aceite de Batana x2 | S13: 26779.5 | T13: -18120.5 | U13: {=IFERROR(_xlfn.IFS(tblPedidos[[#This Row],[estado_operativo]]="ENTREGADO",tblPedidos[[#This Row],[ganancia_calc]],tblPedidos[[#This Row],[estado_operativo]]="DEVOLUCION",tblPedidos[[#This Row],[costo_devolucion_estimado]]),0)} -> 0 | V13: 0 | W13: 64900 | X13: 18120.5 | Y13: 20000 | Z13: 46043 | AA13: 1 | AB13: 0.94027778 | AC13: PENDIENTE | AD13: PENDIENTE | AE13: PENDIENTE
C14: 1030 | D14: 63455546 | E14: 46043 | F14: Carmen Garcia | G14: ENVIA | J14: PENDIENTE | L14: VALLE | M14: CALI | N14: Calle 16 # 45 B bis - 23, Barrio Las Granjas | O14: 3172771840 | P14: {=IFERROR(_xlfn.XLOOKUP(tblPedidos[[#This Row],[id_dropi]],tblNotas[[#This Row],[id__dropi]],tblNotas[[#This Row],[Notas Manuales]], “”, 0),"")} | Q14: Barrio Las Granjas | R14: DUO capilar ADIOS FRIZZ - 500ml x1 | S14: 32946.5 | T14: -10802.8 | U14: {=IFERROR(_xlfn.IFS(tblPedidos[[#This Row],[estado_operativo]]="ENTREGADO",tblPedidos[[#This Row],[ganancia_calc]],tblPedidos[[#This Row],[estado_operativo]]="DEVOLUCION",tblPedidos[[#This Row],[costo_devolucion_estimado]]),0)} -> 0 | V14: 0 | W14: 69900 | X14: 13503.5 | Y14: 23450 | Z14: 46043 | AA14: 1 | AB14: 0.93958333 | AC14: PENDIENTE | AD14: PENDIENTE | AE14: PENDIENTE
C15: 1031 | D15: 63455526 | E15: 46043 | F15: Luisana Rojas | G15: INTERRAPIDISIMO | J15: PENDIENTE | L15: NORTE DE SANTANDER | M15: TIBU | N15: Cliente recoge pedido en oficina de Interrapidisimo en Tibu cliente recoge en esa oficina | O15: 3138816999 | P15: {=IFERROR(_xlfn.XLOOKUP(tblPedidos[[#This Row],[id_dropi]],tblNotas[[#This Row],[id__dropi]],tblNotas[[#This Row],[Notas Manuales]], “”, 0),"")} | Q15: PEDIDO PARA RECOGER EN OFICINA DE INTERRAPIDISIMO | R15: Quemador de grasa Lemme Burn 60 cáps x2 | S15: 20654.5 | T15: -19245.5 | U15: {=IFERROR(_xlfn.IFS(tblPedidos[[#This Row],[estado_operativo]]="ENTREGADO",tblPedidos[[#This Row],[ganancia_calc]],tblPedidos[[#This Row],[estado_operativo]]="DEVOLUCION",tblPedidos[[#This Row],[costo_devolucion_estimado]]),0)} -> 0 | V15: 0 | W15: 89900 | X15: 19245.5 | Y15: 50000 | Z15: 46043 | AA15: 1 | AB15: 0.93888889 | AC15: PENDIENTE | AD15: PENDIENTE | AE15: PENDIENTE
C16: 1028 | D16: 63455501 | E16: 46043 | F16: Marisol Ospina Cortes | G16: INTERRAPIDISIMO | J16: PENDIENTE | L16: CUNDINAMARCA | M16: BOGOTA | N16: Cr 79h N 57g 93 sur, Barrio Porvenir Roma, Kenedy | O16: 3018109025 | P16: {=IFERROR(_xlfn.XLOOKUP(tblPedidos[[#This Row],[id_dropi]],tblNotas[[#This Row],[id__dropi]],tblNotas[[#This Row],[Notas Manuales]], “”, 0),"")} | Q16: Cr 79h N 57g 93 sur, Barrio Porvenir Roma, Kenedy - Casa esquinera | R16: Cepillo Plancha Secador 2 en 1 Alisador x1 | S16: 28779.5 | T16: -11720.5 | U16: {=IFERROR(_xlfn.IFS(tblPedidos[[#This Row],[estado_operativo]]="ENTREGADO",tblPedidos[[#This Row],[ganancia_calc]],tblPedidos[[#This Row],[estado_operativo]]="DEVOLUCION",tblPedidos[[#This Row],[costo_devolucion_estimado]]),0)} -> 0 | V16: 0 | W16: 54900 | X16: 11720.5 | Y16: 14400 | Z16: 46043 | AA16: 1 | AB16: 0.93888889 | AC16: PENDIENTE | AD16: PENDIENTE | AE16: PENDIENTE
C17: 1025 | D17: 63455497 | E17: 46043 | F17: Leidy Zúñiga | G17: INTERRAPIDISIMO | J17: PENDIENTE | L17: TOLIMA | M17: ROVIRA | N17: Cliente recoge pedido en oficina de Interrapidisimo en Rovira cliente recoge en esa oficina | O17: 3115222104 | P17: {=IFERROR(_xlfn.XLOOKUP(tblPedidos[[#This Row],[id_dropi]],tblNotas[[#This Row],[id__dropi]],tblNotas[[#This Row],[Notas Manuales]], “”, 0),"")} | Q17: PEDIDO PARA RECOGER EN OFICINA DE INTERRAPIDISIMO | R17: Quemador de grasa Lemme Burn 60 cáps x2 | S17: 20654.5 | T17: -19245.5 | U17: {=IFERROR(_xlfn.IFS(tblPedidos[[#This Row],[estado_operativo]]="ENTREGADO",tblPedidos[[#This Row],[ganancia_calc]],tblPedidos[[#This Row],[estado_operativo]]="DEVOLUCION",tblPedidos[[#This Row],[costo_devolucion_estimado]]),0)} -> 0 | V17: 0 | W17: 89900 | X17: 19245.5 | Y17: 50000 | Z17: 46043 | AA17: 1 | AB17: 0.93888889 | AC17: PENDIENTE | AD17: PENDIENTE | AE17: PENDIENTE
C18: 1026 | D18: 63455476 | E18: 46043 | F18: Luz Dueñas | G18: INTERRAPIDISIMO | J18: PENDIENTE | L18: CUNDINAMARCA | M18: BOGOTA | N18: Transversal 59 N 74 58 sur, barrio Sierra Morena | O18: 3227178119 | P18: {=IFERROR(_xlfn.XLOOKUP(tblPedidos[[#This Row],[id_dropi]],tblNotas[[#This Row],[id__dropi]],tblNotas[[#This Row],[Notas Manuales]], “”, 0),"")} | R18: Quemador de grasa Lemme Burn 60 cáps x2 | S18: 20654.5 | T18: -19245.5 | U18: {=IFERROR(_xlfn.IFS(tblPedidos[[#This Row],[estado_operativo]]="ENTREGADO",tblPedidos[[#This Row],[ganancia_calc]],tblPedidos[[#This Row],[estado_operativo]]="DEVOLUCION",tblPedidos[[#This Row],[costo_devolucion_estimado]]),0)} -> 0 | V18: 0 | W18: 89900 | X18: 19245.5 | Y18: 50000 | Z18: 46043 | AA18: 1 | AB18: 0.93819444 | AC18: PENDIENTE | AD18: PENDIENTE | AE18: PENDIENTE
C19: 1027 | D19: 63455447 | E19: 46043 | F19: Carolina Hurtado | G19: INTERRAPIDISIMO | J19: PENDIENTE | L19: VALLE | M19: CALI | N19: CLIENTE RECOGE EN OFICINA INTERRAPIDISIMO Cra. 15 #33b-09, Comuna 8, | O19: 3177584912 | P19: {=IFERROR(_xlfn.XLOOKUP(tblPedidos[[#This Row],[id_dropi]],tblNotas[[#This Row],[id__dropi]],tblNotas[[#This Row],[Notas Manuales]], “”, 0),"")} | Q19: PERMITIR QUE EL CLIENTE REVISE EL PEDIDO ANTES DE PAGAR | R19: Quemador de grasa Lemme Burn 60 cáps x1 | S19: 18179.5 | T19: -11720.5 | U19: {=IFERROR(_xlfn.IFS(tblPedidos[[#This Row],[estado_operativo]]="ENTREGADO",tblPedidos[[#This Row],[ganancia_calc]],tblPedidos[[#This Row],[estado_operativo]]="DEVOLUCION",tblPedidos[[#This Row],[costo_devolucion_estimado]]),0)} -> 0 | V19: 0 | W19: 54900 | X19: 11720.5 | Y19: 25000 | Z19: 46043 | AA19: 1 | AB19: 0.9375 | AC19: PENDIENTE | AD19: PENDIENTE | AE19: PENDIENTE
C20: 1017 | D20: 63455323 | E20: 46043 | F20: Brenda Valencia | G20: INTERRAPIDISIMO | J20: PENDIENTE | L20: NARIÑO | M20: TUMACO | N20: OFICINA INTERRAPIDISIMO TUMACO | O20: 3241743932 | P20: {=IFERROR(_xlfn.XLOOKUP(tblPedidos[[#This Row],[id_dropi]],tblNotas[[#This Row],[id__dropi]],tblNotas[[#This Row],[Notas Manuales]], “”, 0),"")} | Q20: CLIENTE RECLAMA EN OFICINA INTERRAPIDISIMO TUMACO | R20: Cepillo Plancha Secador 2 en 1 Alisador x1 | S20: 22829.5 | T20: -17670.5 | U20: {=IFERROR(_xlfn.IFS(tblPedidos[[#This Row],[estado_operativo]]="ENTREGADO",tblPedidos[[#This Row],[ganancia_calc]],tblPedidos[[#This Row],[estado_operativo]]="DEVOLUCION",tblPedidos[[#This Row],[costo_devolucion_estimado]]),0)} -> 0 | V20: 0 | W20: 54900 | X20: 17670.5 | Y20: 14400 | Z20: 46043 | AA20: 1 | AB20: 0.93680556 | AC20: PENDIENTE | AD20: PENDIENTE | AE20: PENDIENTE
C21: 1007 | D21: 63455271 | E21: 46043 | F21: Nancy Cruz | G21: INTERRAPIDISIMO | J21: PENDIENTE | L21: RISARALDA | M21: PEREIRA | N21: Manzana 9 casa 15 piso 2 Barrio perla del Sur | O21: 3014683522 | P21: {=IFERROR(_xlfn.XLOOKUP(tblPedidos[[#This Row],[id_dropi]],tblNotas[[#This Row],[id__dropi]],tblNotas[[#This Row],[Notas Manuales]], “”, 0),"")} | Q21: Barrio perla del Sur | R21: DUO capilar ADIOS FRIZZ - 500ml x1 | S21: 34054.5 | T21: -12395.5 | U21: {=IFERROR(_xlfn.IFS(tblPedidos[[#This Row],[estado_operativo]]="ENTREGADO",tblPedidos[[#This Row],[ganancia_calc]],tblPedidos[[#This Row],[estado_operativo]]="DEVOLUCION",tblPedidos[[#This Row],[costo_devolucion_estimado]]),0)} -> 0 | V21: 0 | W21: 69900 | X21: 12395.5 | Y21: 23450 | Z21: 46043 | AA21: 1 | AB21: 0.93680556 | AC21: PENDIENTE | AD21: PENDIENTE | AE21: PENDIENTE
C22: 1008 | D22: 63455085 | E22: 46043 | F22: Geidis Araujo | G22: INTERRAPIDISIMO | J22: PENDIENTE | L22: ATLANTICO | M22: SABANALARGA | N22: OFICINA INTERRAPIDISIMO SABANALARGA | O22: 3116626088 | P22: {=IFERROR(_xlfn.XLOOKUP(tblPedidos[[#This Row],[id_dropi]],tblNotas[[#This Row],[id__dropi]],tblNotas[[#This Row],[Notas Manuales]], “”, 0),"")} | Q22: CLIENTE RECLAMA EN OFICINA INTERRAPIDISIMO SABANALARGA | R22: Cepillo Plancha Secador 2 en 1 Alisador x2 | S22: 27529.5 | T22: -18570.5 | U22: {=IFERROR(_xlfn.IFS(tblPedidos[[#This Row],[estado_operativo]]="ENTREGADO",tblPedidos[[#This Row],[ganancia_calc]],tblPedidos[[#This Row],[estado_operativo]]="DEVOLUCION",tblPedidos[[#This Row],[costo_devolucion_estimado]]),0)} -> 0 | V22: 0 | W22: 74900 | X22: 18570.5 | Y22: 28800 | Z22: 46043 | AA22: 1 | AB22: 0.93541667 | AC22: PENDIENTE | AD22: PENDIENTE | AE22: PENDIENTE
C23: 1009 | D23: 63454946 | E23: 46043 | F23: Lyda Guzmán | G23: INTERRAPIDISIMO | J23: PENDIENTE | L23: CUNDINAMARCA | M23: BOGOTA | N23: Cra 71b bis # 12-30 torre 1 apto 203 Conj Recodo de Alsacia, Ciudad Alsacia la nueva | O23: 3125652470 | P23: {=IFERROR(_xlfn.XLOOKUP(tblPedidos[[#This Row],[id_dropi]],tblNotas[[#This Row],[id__dropi]],tblNotas[[#This Row],[Notas Manuales]], “”, 0),"")} | Q23: Conjunto Recodo de Alsacia, Ciudad Alsacia la nueva | R23: DUO capilar ADIOS FRIZZ - 500ml x1 | S23: 28104.5 | T23: -18345.5 | U23: {=IFERROR(_xlfn.IFS(tblPedidos[[#This Row],[estado_operativo]]="ENTREGADO",tblPedidos[[#This Row],[ganancia_calc]],tblPedidos[[#This Row],[estado_operativo]]="DEVOLUCION",tblPedidos[[#This Row],[costo_devolucion_estimado]]),0)} -> 0 | V23: 0 | W23: 69900 | X23: 18345.5 | Y23: 23450 | Z23: 46043 | AA23: 1 | AB23: 0.93472222 | AC23: PENDIENTE | AD23: PENDIENTE | AE23: PENDIENTE
C24: 1006 | D24: 63454914 | E24: 46043 | F24: Rosita Palacios | G24: INTERRAPIDISIMO | J24: PENDIENTE | L24: PUTUMAYO | M24: PUERTO CAICEDO | N24: Cliente recoge pedido en oficina de Interrapidisimo en Puerto Caicedo cliente recoge en esa oficina | O24: 3219523165 | P24: {=IFERROR(_xlfn.XLOOKUP(tblPedidos[[#This Row],[id_dropi]],tblNotas[[#This Row],[id__dropi]],tblNotas[[#This Row],[Notas Manuales]], “”, 0),"")} | Q24: PEDIDO PARA RECOGER EN OFICINA DE INTERRAPIDISIMO | R24: Quemador de grasa Lemme Burn 60 cáps x2 | S24: 20654.5 | T24: -19245.5 | U24: {=IFERROR(_xlfn.IFS(tblPedidos[[#This Row],[estado_operativo]]="ENTREGADO",tblPedidos[[#This Row],[ganancia_calc]],tblPedidos[[#This Row],[estado_operativo]]="DEVOLUCION",tblPedidos[[#This Row],[costo_devolucion_estimado]]),0)} -> 0 | V24: 0 | W24: 89900 | X24: 19245.5 | Y24: 50000 | Z24: 46043 | AA24: 1 | AB24: 0.93402778 | AC24: PENDIENTE | AD24: PENDIENTE | AE24: PENDIENTE
C25: 1003 | D25: 63454816 | E25: 46043 | F25: MONICA ASTRITH JAIME | G25: INTERRAPIDISIMO | J25: PENDIENTE | L25: NORTE DE SANTANDER | M25: ABREGO | N25: CARRERA 3 #15-21. A BARRIO SAN CARLOS. | O25: 3133586050 | P25: {=IFERROR(_xlfn.XLOOKUP(tblPedidos[[#This Row],[id_dropi]],tblNotas[[#This Row],[id__dropi]],tblNotas[[#This Row],[Notas Manuales]], “”, 0),"")} | R25: Quemador de grasa Lemme Burn 60 cáps x2 | S25: 15879.5 | T25: -19020.5 | U25: {=IFERROR(_xlfn.IFS(tblPedidos[[#This Row],[estado_operativo]]="ENTREGADO",tblPedidos[[#This Row],[ganancia_calc]],tblPedidos[[#This Row],[estado_operativo]]="DEVOLUCION",tblPedidos[[#This Row],[costo_devolucion_estimado]]),0)} -> 0 | V25: 0 | W25: 84900 | X25: 19020.5 | Y25: 50000 | Z25: 46043 | AA25: 1 | AB25: 0.93402778 | AC25: PENDIENTE | AD25: PENDIENTE | AE25: PENDIENTE
C26: 1004 | D26: 63454680 | E26: 46043 | F26: Katy Yulieth Romero Luna | G26: INTERRAPIDISIMO | J26: PENDIENTE | L26: SUCRE | M26: SAN MARCOS | N26: 𝒄𝒂𝒍𝒍𝒆 23 𝒄𝒂𝒓𝒆𝒓𝒂 35 𝒏.𝒂7.𝒃 𝒑𝒖𝒆𝒓𝒕𝒐 𝒍𝒐𝒑𝒆𝒛 | O26: 3246209286 | P26: {=IFERROR(_xlfn.XLOOKUP(tblPedidos[[#This Row],[id_dropi]],tblNotas[[#This Row],[id__dropi]],tblNotas[[#This Row],[Notas Manuales]], “”, 0),"")} | R26: Cepillo Plancha Secador 2 en 1 Alisador x2 | S26: 27529.5 | T26: -18570.5 | U26: {=IFERROR(_xlfn.IFS(tblPedidos[[#This Row],[estado_operativo]]="ENTREGADO",tblPedidos[[#This Row],[ganancia_calc]],tblPedidos[[#This Row],[estado_operativo]]="DEVOLUCION",tblPedidos[[#This Row],[costo_devolucion_estimado]]),0)} -> 0 | V26: 0 | W26: 74900 | X26: 18570.5 | Y26: 28800 | Z26: 46043 | AA26: 1 | AB26: 0.93263889 | AC26: PENDIENTE | AD26: PENDIENTE | AE26: PENDIENTE
C27: 1005 | D27: 63454655 | E27: 46043 | F27: Ester Julia Nazarit | G27: INTERRAPIDISIMO | J27: PENDIENTE | L27: CAUCA | M27: SANTANDER DE QUILICHAO | N27: Carrera 19 #2-72 barrio porvenir. | O27: 3216764581 | P27: {=IFERROR(_xlfn.XLOOKUP(tblPedidos[[#This Row],[id_dropi]],tblNotas[[#This Row],[id__dropi]],tblNotas[[#This Row],[Notas Manuales]], “”, 0),"")} | R27: Aceite de Batana x4 | S27: 35429.5 | T27: -19470.5 | U27: {=IFERROR(_xlfn.IFS(tblPedidos[[#This Row],[estado_operativo]]="ENTREGADO",tblPedidos[[#This Row],[ganancia_calc]],tblPedidos[[#This Row],[estado_operativo]]="DEVOLUCION",tblPedidos[[#This Row],[costo_devolucion_estimado]]),0)} -> 0 | V27: 0 | W27: 94900 | X27: 19470.5 | Y27: 40000 | Z27: 46043 | AA27: 1 | AB27: 0.93263889 | AC27: PENDIENTE | AD27: PENDIENTE | AE27: PENDIENTE
C28: 1014 | D28: 63454646 | E28: 46043 | F28: Milagro Pallares | G28: INTERRAPIDISIMO | J28: PENDIENTE | L28: ATLANTICO | M28: MALAMBO | N28: Calle 5 # 17 - 03 Barrio Abajo | O28: 3115287480 | P28: {=IFERROR(_xlfn.XLOOKUP(tblPedidos[[#This Row],[id_dropi]],tblNotas[[#This Row],[id__dropi]],tblNotas[[#This Row],[Notas Manuales]], “”, 0),"")} | Q28: Barrio Abajo | R28: DUO capilar ADIOS FRIZZ - 300 ml x1 | S28: 22054.5 | T28: -17895.5 | U28: {=IFERROR(_xlfn.IFS(tblPedidos[[#This Row],[estado_operativo]]="ENTREGADO",tblPedidos[[#This Row],[ganancia_calc]],tblPedidos[[#This Row],[estado_operativo]]="DEVOLUCION",tblPedidos[[#This Row],[costo_devolucion_estimado]]),0)} -> 0 | V28: 0 | W28: 59900 | X28: 17895.5 | Y28: 19950 | Z28: 46043 | AA28: 1 | AB28: 0.93263889 | AC28: PENDIENTE | AD28: PENDIENTE | AE28: PENDIENTE
C29: 1015 | D29: 63454453 | E29: 46043 | F29: Nidia Perdomo | G29: INTERRAPIDISIMO | J29: PENDIENTE | L29: TOLIMA | M29: IBAGUE | N29: Manzana C - casa #15 Barrio San Antonio | O29: 3228781846 | P29: {=IFERROR(_xlfn.XLOOKUP(tblPedidos[[#This Row],[id_dropi]],tblNotas[[#This Row],[id__dropi]],tblNotas[[#This Row],[Notas Manuales]], “”, 0),"")} | Q29: Manzana C - casa 15 Barrio San Antonio | R29: DUO capilar ADIOS FRIZZ - 500ml x1 | S29: 30551 | T29: -15899 | U29: {=IFERROR(_xlfn.IFS(tblPedidos[[#This Row],[estado_operativo]]="ENTREGADO",tblPedidos[[#This Row],[ganancia_calc]],tblPedidos[[#This Row],[estado_operativo]]="DEVOLUCION",tblPedidos[[#This Row],[costo_devolucion_estimado]]),0)} -> 0 | V29: 0 | W29: 69900 | X29: 15899 | Y29: 23450 | Z29: 46043 | AA29: 1 | AB29: 0.93055556 | AC29: PENDIENTE | AD29: PENDIENTE | AE29: PENDIENTE
C30: 1016 | D30: 63454427 | E30: 46043 | F30: Diana Ochoa | G30: INTERRAPIDISIMO | J30: PENDIENTE | L30: BOYACA | M30: TUNJA | N30: Carrera 10 #64 b 79 apto 202 torre 30, Parque residencial el refugio | O30: 3115127049 | P30: {=IFERROR(_xlfn.XLOOKUP(tblPedidos[[#This Row],[id_dropi]],tblNotas[[#This Row],[id__dropi]],tblNotas[[#This Row],[Notas Manuales]], “”, 0),"")} | R30: Quemador de grasa Lemme Burn 60 cáps x2 | S30: 15879.5 | T30: -19020.5 | U30: {=IFERROR(_xlfn.IFS(tblPedidos[[#This Row],[estado_operativo]]="ENTREGADO",tblPedidos[[#This Row],[ganancia_calc]],tblPedidos[[#This Row],[estado_operativo]]="DEVOLUCION",tblPedidos[[#This Row],[costo_devolucion_estimado]]),0)} -> 0 | V30: 0 | W30: 84900 | X30: 19020.5 | Y30: 50000 | Z30: 46043 | AA30: 1 | AB30: 0.93055556 | AC30: PENDIENTE | AD30: PENDIENTE | AE30: PENDIENTE
C31: 1013 | D31: 63454372 | E31: 46043 | F31: Liliana Duran | G31: INTERRAPIDISIMO | J31: PENDIENTE | L31: NORTE DE SANTANDER | M31: TEORAMA | N31: CLIENTE RECOGE EN OFICINA INTERRAPIDISIMO Calle 4 #8-29 ofc 3550 | O31: 3235242496 | P31: {=IFERROR(_xlfn.XLOOKUP(tblPedidos[[#This Row],[id_dropi]],tblNotas[[#This Row],[id__dropi]],tblNotas[[#This Row],[Notas Manuales]], “”, 0),"")} | Q31: PEDIDO PARA RECOGER EN OFICINA DE INTERRAPIDISIMO | R31: Truly Soft Serve + T. Glazed Donut 60ml x1 | S31: 26554.5 | T31: -18345.5 | U31: {=IFERROR(_xlfn.IFS(tblPedidos[[#This Row],[estado_operativo]]="ENTREGADO",tblPedidos[[#This Row],[ganancia_calc]],tblPedidos[[#This Row],[estado_operativo]]="DEVOLUCION",tblPedidos[[#This Row],[costo_devolucion_estimado]]),0)} -> 0 | V31: 0 | W31: 69900 | X31: 18345.5 | Y31: 25000 | Z31: 46043 | AA31: 1 | AB31: 0.92986111 | AC31: PENDIENTE | AD31: PENDIENTE | AE31: PENDIENTE
C32: 1010 | D32: 63454221 | E32: 46043 | F32: Nancy María Vélez | G32: ENVIA | J32: PENDIENTE | L32: ANTIOQUIA | M32: BELLO | N32: Diagonal 53 #42-71 Niquia | O32: 3122842049 | P32: {=IFERROR(_xlfn.XLOOKUP(tblPedidos[[#This Row],[id_dropi]],tblNotas[[#This Row],[id__dropi]],tblNotas[[#This Row],[Notas Manuales]], “”, 0),"")} | R32: Truly Soft Serve + T. Glazed Donut 60ml x1 | S32: 29236.5 | T32: -12530.8 | U32: {=IFERROR(_xlfn.IFS(tblPedidos[[#This Row],[estado_operativo]]="ENTREGADO",tblPedidos[[#This Row],[ganancia_calc]],tblPedidos[[#This Row],[estado_operativo]]="DEVOLUCION",tblPedidos[[#This Row],[costo_devolucion_estimado]]),0)} -> 0 | V32: 0 | W32: 69900 | X32: 15663.5 | Y32: 25000 | Z32: 46043 | AA32: 1 | AB32: 0.92916667 | AC32: PENDIENTE | AD32: PENDIENTE | AE32: PENDIENTE
C33: 1011 | D33: 63454140 | E33: 46043 | F33: Wilerma Ruiz | G33: INTERRAPIDISIMO | J33: PENDIENTE | L33: BOYACA | M33: SACHICA | N33: Calle 3 # 1 - 21 centro sachica | O33: 3217320042 | P33: {=IFERROR(_xlfn.XLOOKUP(tblPedidos[[#This Row],[id_dropi]],tblNotas[[#This Row],[id__dropi]],tblNotas[[#This Row],[Notas Manuales]], “”, 0),"")} | R33: Cepillo Plancha Secador 2 en 1 Alisador x2 | S33: 22754.5 | T33: -18345.5 | U33: {=IFERROR(_xlfn.IFS(tblPedidos[[#This Row],[estado_operativo]]="ENTREGADO",tblPedidos[[#This Row],[ganancia_calc]],tblPedidos[[#This Row],[estado_operativo]]="DEVOLUCION",tblPedidos[[#This Row],[costo_devolucion_estimado]]),0)} -> 0 | V33: 0 | W33: 69900 | X33: 18345.5 | Y33: 28800 | Z33: 46043 | AA33: 1 | AB33: 0.92847222 | AC33: PENDIENTE | AD33: PENDIENTE | AE33: PENDIENTE
C34: 1012 | D34: 63454064 | E34: 46043 | F34: Eloísa del Carmen Andueza Burgos | G34: INTERRAPIDISIMO | J34: PENDIENTE | L34: CASANARE | M34: YOPAL | N34: Cliente recoge pedido en oficina de Interrapidisimo en Yopal cliente recoge en esa oficina | O34: 3227649115 | P34: {=IFERROR(_xlfn.XLOOKUP(tblPedidos[[#This Row],[id_dropi]],tblNotas[[#This Row],[id__dropi]],tblNotas[[#This Row],[Notas Manuales]], “”, 0),"")} | Q34: PEDIDO PARA RECOGER EN OFICINA DE INTERRAPIDISIMO | R34: Serum despigmentante SMOOTH LEGEND 60ml x1 | S34: 24004.5 | T34: -17895.5 | U34: {=IFERROR(_xlfn.IFS(tblPedidos[[#This Row],[estado_operativo]]="ENTREGADO",tblPedidos[[#This Row],[ganancia_calc]],tblPedidos[[#This Row],[estado_operativo]]="DEVOLUCION",tblPedidos[[#This Row],[costo_devolucion_estimado]]),0)} -> 0 | V34: 0 | W34: 59900 | X34: 17895.5 | Y34: 18000 | Z34: 46043 | AA34: 1 | AB34: 0.92777778 | AC34: PENDIENTE | AD34: PENDIENTE | AE34: PENDIENTE
C35: 1051 | D35: 63453464 | E35: 46043 | F35: Martin Eduardo Potes | G35: INTERRAPIDISIMO | J35: PENDIENTE | L35: ATLANTICO | M35: JUAN DE ACOSTA | N35: OFICINA INTERRAPIDISIMO JUAN DE ACOSTA | O35: 3008937303 | P35: {=IFERROR(_xlfn.XLOOKUP(tblPedidos[[#This Row],[id_dropi]],tblNotas[[#This Row],[id__dropi]],tblNotas[[#This Row],[Notas Manuales]], “”, 0),"")} | Q35: CLIENTE RECLAMA EN OFICINA DE INTERRAPIDISIMO JUAN DE ACOSTA. | R35: Bee Venom BSWELL x1 + Beevana crema +Varicose veins x2 | S35: 24879.5 | T35: -19020.5 | U35: {=IFERROR(_xlfn.IFS(tblPedidos[[#This Row],[estado_operativo]]="ENTREGADO",tblPedidos[[#This Row],[ganancia_calc]],tblPedidos[[#This Row],[estado_operativo]]="DEVOLUCION",tblPedidos[[#This Row],[costo_devolucion_estimado]]),0)} -> 0 | V35: 0 | W35: 84900 | X35: 19020.5 | Y35: 41000 | Z35: 46043 | AA35: 1 | AB35: 0.92361111 | AC35: PENDIENTE | AD35: PENDIENTE | AE35: PENDIENTE
C36: 1052 | D36: 63453457 | E36: 46043 | F36: María Dihanora Cárdenas | G36: INTERRAPIDISIMO | J36: PENDIENTE | L36: PUTUMAYO | M36: VILLAGARZON | N36: Cliente recoge pedido en oficina de Interrapidisimo en Villagarzon cliente recoge en esa oficina | O36: 3503802979 | P36: {=IFERROR(_xlfn.XLOOKUP(tblPedidos[[#This Row],[id_dropi]],tblNotas[[#This Row],[id__dropi]],tblNotas[[#This Row],[Notas Manuales]], “”, 0),"")} | Q36: PEDIDO PARA RECOGER EN OFICINA DE INTERRAPIDISIMO | R36: DUO capilar ADIOS FRIZZ - 500ml x2 | S36: 42854.5 | T36: -20145.5 | U36: {=IFERROR(_xlfn.IFS(tblPedidos[[#This Row],[estado_operativo]]="ENTREGADO",tblPedidos[[#This Row],[ganancia_calc]],tblPedidos[[#This Row],[estado_operativo]]="DEVOLUCION",tblPedidos[[#This Row],[costo_devolucion_estimado]]),0)} -> 0 | V36: 0 | W36: 109900 | X36: 20145.5 | Y36: 46900 | Z36: 46043 | AA36: 1 | AB36: 0.92361111 | AC36: PENDIENTE | AD36: PENDIENTE | AE36: PENDIENTE
C37: 1053 | D37: 63453247 | E37: 46043 | F37: Sandra Lozano | G37: INTERRAPIDISIMO | J37: PENDIENTE | L37: CASANARE | M37: VILLANUEVA (C) | N37: Cliente recoge pedido en oficina de Interrapidisimo en Villanueva (c) cliente recoge en esa oficina | O37: 3132166337 | P37: {=IFERROR(_xlfn.XLOOKUP(tblPedidos[[#This Row],[id_dropi]],tblNotas[[#This Row],[id__dropi]],tblNotas[[#This Row],[Notas Manuales]], “”, 0),"")} | Q37: PEDIDO PARA RECOGER EN OFICINA DE INTERRAPIDISIMO | R37: Quemador de grasa Lemme Burn 60 cáps x2 | S37: 20654.5 | T37: -19245.5 | U37: {=IFERROR(_xlfn.IFS(tblPedidos[[#This Row],[estado_operativo]]="ENTREGADO",tblPedidos[[#This Row],[ganancia_calc]],tblPedidos[[#This Row],[estado_operativo]]="DEVOLUCION",tblPedidos[[#This Row],[costo_devolucion_estimado]]),0)} -> 0 | V37: 0 | W37: 89900 | X37: 19245.5 | Y37: 50000 | Z37: 46043 | AA37: 1 | AB37: 0.92152778 | AC37: PENDIENTE | AD37: PENDIENTE | AE37: PENDIENTE
C38: 1050 | D38: 63452706 | E38: 46043 | F38: María Avila | G38: INTERRAPIDISIMO | J38: PENDIENTE | L38: CUNDINAMARCA | M38: BOGOTA | N38: Cra 9 # 81-85 sur | O38: 3133600679 | P38: {=IFERROR(_xlfn.XLOOKUP(tblPedidos[[#This Row],[id_dropi]],tblNotas[[#This Row],[id__dropi]],tblNotas[[#This Row],[Notas Manuales]], “”, 0),"")} | R38: Quemador de grasa Lemme Burn 60 cáps x2 | S38: 20654.5 | T38: -19245.5 | U38: {=IFERROR(_xlfn.IFS(tblPedidos[[#This Row],[estado_operativo]]="ENTREGADO",tblPedidos[[#This Row],[ganancia_calc]],tblPedidos[[#This Row],[estado_operativo]]="DEVOLUCION",tblPedidos[[#This Row],[costo_devolucion_estimado]]),0)} -> 0 | V38: 0 | W38: 89900 | X38: 19245.5 | Y38: 50000 | Z38: 46043 | AA38: 1 | AB38: 0.91805556 | AC38: PENDIENTE | AD38: PENDIENTE | AE38: PENDIENTE
C39: 1047 | D39: 63452558 | E39: 46043 | F39: Rafaél Varon Gámez | G39: INTERRAPIDISIMO | J39: PENDIENTE | L39: CUNDINAMARCA | M39: GIRARDOT | N39: Manzana 77 casa 15 barrio Kennedy | O39: 3153302201 | P39: {=IFERROR(_xlfn.XLOOKUP(tblPedidos[[#This Row],[id_dropi]],tblNotas[[#This Row],[id__dropi]],tblNotas[[#This Row],[Notas Manuales]], “”, 0),"")} | R39: Quemador de grasa Lemme Burn 60 cáps x2 | S39: 20654.5 | T39: -19245.5 | U39: {=IFERROR(_xlfn.IFS(tblPedidos[[#This Row],[estado_operativo]]="ENTREGADO",tblPedidos[[#This Row],[ganancia_calc]],tblPedidos[[#This Row],[estado_operativo]]="DEVOLUCION",tblPedidos[[#This Row],[costo_devolucion_estimado]]),0)} -> 0 | V39: 0 | W39: 89900 | X39: 19245.5 | Y39: 50000 | Z39: 46043 | AA39: 1 | AB39: 0.91736111 | AC39: PENDIENTE | AD39: PENDIENTE | AE39: PENDIENTE
C40: 1048 | D40: 63452433 | E40: 46043 | F40: maria yoleida banguera | G40: INTERRAPIDISIMO | J40: PENDIENTE | L40: CAUCA | M40: PUERTO TEJADA | N40: Carrera11 calle #18 - 02 barrio la cabaña | O40: 3225236597 | P40: {=IFERROR(_xlfn.XLOOKUP(tblPedidos[[#This Row],[id_dropi]],tblNotas[[#This Row],[id__dropi]],tblNotas[[#This Row],[Notas Manuales]], “”, 0),"")} | R40: Bee Venom BSWELL x1 + Beevana crema +Varicose veins x1 | S40: 17004.5 | T40: -17895.5 | U40: {=IFERROR(_xlfn.IFS(tblPedidos[[#This Row],[estado_operativo]]="ENTREGADO",tblPedidos[[#This Row],[ganancia_calc]],tblPedidos[[#This Row],[estado_operativo]]="DEVOLUCION",tblPedidos[[#This Row],[costo_devolucion_estimado]]),0)} -> 0 | V40: 0 | W40: 59900 | X40: 17895.5 | Y40: 25000 | Z40: 46043 | AA40: 1 | AB40: 0.91597222 | AC40: PENDIENTE | AD40: PENDIENTE | AE40: PENDIENTE
...

Sheet NOTAS
A1: id__dropi | B1: Nombre | C1: telefono | D1: Producto | E1: Oficina | F1: Notas Manuales
A2: 61322803 | B2: =VLOOKUP(tblNotas[[#This Row],[id__dropi]],Pedidos!D:O,5,0) -> #N/A | C2: =VLOOKUP(tblNotas[[#This Row],[id__dropi]],Pedidos!D:O,12,0) -> #N/A | F2: llamado 3 veces
A3: 61584447 | B3: =VLOOKUP(tblNotas[[#This Row],[id__dropi]],Pedidos!D:O,5,0) -> #N/A | C3: =VLOOKUP(tblNotas[[#This Row],[id__dropi]],Pedidos!D:O,12,0) -> #N/A | F3: llame 10 veces
A4: 61687973 | B4: =VLOOKUP(tblNotas[[#This Row],[id__dropi]],Pedidos!D:O,5,0) -> 0 | C4: =VLOOKUP(tblNotas[[#This Row],[id__dropi]],Pedidos!D:O,12,0) -> 3128387983 | F4: llame 10 veces
A5: 61716971 | B5: =VLOOKUP(tblNotas[[#This Row],[id__dropi]],Pedidos!D:O,5,0) -> 0 | C5: =VLOOKUP(tblNotas[[#This Row],[id__dropi]],Pedidos!D:O,12,0) -> 3043681389
A6: 61715914 | B6: =VLOOKUP(tblNotas[[#This Row],[id__dropi]],Pedidos!D:O,5,0) -> 0 | C6: =VLOOKUP(tblNotas[[#This Row],[id__dropi]],Pedidos!D:O,12,0) -> 3122504723
A7: 61683459 | B7: =VLOOKUP(tblNotas[[#This Row],[id__dropi]],Pedidos!D:O,5,0) -> 0 | C7: =VLOOKUP(tblNotas[[#This Row],[id__dropi]],Pedidos!D:O,12,0) -> 3125206068
A8: 61808621 | B8: =VLOOKUP(tblNotas[[#This Row],[id__dropi]],Pedidos!D:O,5,0) -> 0 | C8: =VLOOKUP(tblNotas[[#This Row],[id__dropi]],Pedidos!D:O,12,0) -> 3116739503
A9: 61808234 | B9: =VLOOKUP(tblNotas[[#This Row],[id__dropi]],Pedidos!D:O,5,0) -> 0 | C9: =VLOOKUP(tblNotas[[#This Row],[id__dropi]],Pedidos!D:O,12,0) -> 3205381934
A10: 61788521 | B10: =VLOOKUP(tblNotas[[#This Row],[id__dropi]],Pedidos!D:O,5,0) -> 0 | C10: =VLOOKUP(tblNotas[[#This Row],[id__dropi]],Pedidos!D:O,12,0) -> 3242038699
A11: 61935012 | B11: =VLOOKUP(tblNotas[[#This Row],[id__dropi]],Pedidos!D:O,5,0) -> 0 | C11: =VLOOKUP(tblNotas[[#This Row],[id__dropi]],Pedidos!D:O,12,0) -> 3007515120
A12: 61884335 | B12: =VLOOKUP(tblNotas[[#This Row],[id__dropi]],Pedidos!D:O,5,0) -> 0 | C12: =VLOOKUP(tblNotas[[#This Row],[id__dropi]],Pedidos!D:O,12,0) -> 3113614112
A13: 62055562 | B13: =VLOOKUP(tblNotas[[#This Row],[id__dropi]],Pedidos!D:O,5,0) -> 0 | C13: =VLOOKUP(tblNotas[[#This Row],[id__dropi]],Pedidos!D:O,12,0) -> 3017501313
A14: 62054687 | B14: =VLOOKUP(tblNotas[[#This Row],[id__dropi]],Pedidos!D:O,5,0) -> 0 | C14: =VLOOKUP(tblNotas[[#This Row],[id__dropi]],Pedidos!D:O,12,0) -> 3247119922
A15: 62174626 | B15: =VLOOKUP(tblNotas[[#This Row],[id__dropi]],Pedidos!D:O,5,0) -> 0 | C15: =VLOOKUP(tblNotas[[#This Row],[id__dropi]],Pedidos!D:O,12,0) -> 3136242428
A16: 62172963 | B16: =VLOOKUP(tblNotas[[#This Row],[id__dropi]],Pedidos!D:O,5,0) -> 0 | C16: =VLOOKUP(tblNotas[[#This Row],[id__dropi]],Pedidos!D:O,12,0) -> 3123347964
... A71: 63102169 | B71: =VLOOKUP(tblNotas[[#This Row],[id__dropi]],Pedidos!D:O,5,0) -> 0 | C71: =VLOOKUP(tblNotas[[#This Row],[id__dropi]],Pedidos!D:O,12,0) -> 3203916924

Sheet Mapeo_Estados
A1: Mapeo de estados (Dropi/Transportadoras) → tus estados
A3: transportadora (opcional) | B3: estatus_original | C3: ultimo_movimiento (opcional) | D3: estado_unificado | F3: Estados estándar
B4: ANULADO | D4: ANULADO | F4: PENDIENTE | I4: estatus_original
B5: CANCELADO | D5: CANCELADO | F5: ORIGEN | I5: estado_unificado
B6: EN BODEGA DESTINO | D6: DESTINO | F6: TRÁNSITO
B7: DEVOLUCION | D7: DEVOLUCION | F7: DESTINO
B8: ENTREGADO | D8: ENTREGADO | F8: REPARTO
B9: NOVEDAD | D9: NOVEDAD | F9: ENTREGADO
B10: NOVEDAD SOLUCIONADA | D10: NOVEDAD SOLUCIONADA | F10: DEVOLUCIÓN
B11: OFICINA | D11: OFICINA | F11: NOVEDAD
B12: RECLAME EN OFICINA | D12: OFICINA | F12: NOVEDAD SOLUCIONADA
B13: GUIA_GENERADA | D13: ORIGEN | F13: OFICINA
B14: GUIA_GENERADA | D14: ORIGEN | F14: OFICINA 1
B15: PREPARADO PARA TRANSPORTADORA | D15: ORIGEN | F15: CANCELADO
B16: PENDIENTE | D16: PENDIENTE | F16: SINIESTRO / EXTRAVIADO
B17: EN RUTA | D17: REPARTO
B18: EN REPARTO | D18: REPARTO
B19: INTENTO DE ENTREGA | D19: REPARTO
B20: EN RUTA | D20: REPARTO
B21: EN REPARTO | D21: REPARTO
B22: DESPACHADA | D22: TRANSITO
B23: EN BODEGA TRANSPORTADORA | D23: TRANSITO
B24: PENDIENTE | D24: PENDIENTE
B25: PENDIENTE CONFIRMACION
B26: PENDIENTE
B27: GUIA_GENERADA | D27: ORIGEN
B28: GUIA_ANULADA | D28: CANCELADO
B29: CANCELADO
B30: RECHAZADO | D30: CANCELADO
B31: ENTREGADO
B32: DEVOLUCION
B33: NOVEDAD SOLUCIONADA
B34: PREPARADO PARA TRANSPORTADORA
B35: INDEMNIZADA POR DROPI
B36: DEVOLUCION EN TRANSITO
B37: ENTREGADO A TRANSPORTADORA | D37: ORIGEN
B38: EN BODEGA DROPI | D38: ORIGEN
B39: RECOGIDO POR DROPI | D39: ORIGEN
B40: RECIBIDO PAU
B41: RECIBIDO DEL CLIENTE
...

Sheet Dashboard_Pro
A1: Dropi • Dashboard PRO | K1: Actualizado: | L1: =TODAY() -> 46047
B4: Pedidos (Total) | F4: Entregados | J4: Devoluciones
B5: =ROWS(tblPedidos[id_dropi]) -> 1064 | F5: =COUNTIFS(tblPedidos[estado_operativo],"ENTREGADO") -> 567 | J5: =COUNTIFS(tblPedidos[estado_operativo],"DEVOL*") -> 54
B6: Datos → Actualizar todo | F6: Datos → Actualizar todo | J6: Datos → Actualizar todo
B8: % Devolución | F8: Pendientes | J8: Novedad
B9: =IFERROR(COUNTIFS(tblPedidos[estado_operativo],"DEVOL*")/ROWS(tblPedidos[id_dropi]),0) -> 0.05075188 | F9: =MAX(0, ROWS(tblPedidos[id_dropi]) - COUNTIFS(tblPedidos[estado_operativo],"ENTREG*") - COUNTIFS(tblPedidos[estado_operativo],"DEVOL*") - COUNTIFS(tblPedidos[estado_operativo],"CANCEL*") - COUNTIFS(tblPedidos[estado_operativo],"ANUL*") ) -> 425 | J9: =COUNTIFS(tblPedidos[estado_operativo],"NOVEDAD*") -> 33
B10: Datos → Actualizar todo | F10: Datos → Actualizar todo | J10: Datos → Actualizar todo
B12: Costo devoluciones | F12: Ganancia total | J12: Ventas total
B13: =IFERROR(SUMIFS(tblPedidos[costo_devolucion_estimado],tblPedidos[estado_operativo],"DEVOLUCIÓN"),0) -> 0 | F13: =SUM((tblPedidos[cartera_aplicada])) -> 53491532 | J13: =IFERROR(SUM(#REF!),0) -> 0
B14: Datos → Actualizar todo | F14: Datos → Actualizar todo | J14: Datos → Actualizar todo
B16: Distribución por estado | F16: Devolución por transportadora
B17: Estado | C17: Pedidos | F17: Transportadora | G17: Pedidos | H17: Entregados | I17: Devolución | J17: % Devol. | K17: % Entr
B18: PENDIENTE | C18: =IFERROR(COUNTIFS(tblPedidos[estado_operativo],B18),0) -> 62 | F18: ENVIA | G18: =COUNTIFS(tblPedidos[transportadora],tblTransportadora[[#This Row],[Transportadora]]) -> 259 | H18: =COUNTIFS(tblPedidos[transportadora],tblTransportadora[[#This Row],[Transportadora]],tblPedidos[estado_operativo],"ENTREGADO") -> 135 | I18: =COUNTIFS(tblPedidos[transportadora],tblTransportadora[[#This Row],[Transportadora]],tblPedidos[estado_operativo],"DEVOLUCION") -> 6 | J18: =IFERROR(tblTransportadora[[#This Row],[Devolución]]/tblTransportadora[[#This Row],[Pedidos]],0) -> 0.023166023 | K18: =IFERROR(tblTransportadora[[#This Row],[Entregados]]/tblTransportadora[[#This Row],[Pedidos]],0) -> 0.52123552
B19: ORIGEN | C19: =IFERROR(COUNTIFS(tblPedidos[estado_operativo],B19),0) -> 136 | F19: INTERRAPIDISIMO | G19: =COUNTIFS(tblPedidos[transportadora],tblTransportadora[[#This Row],[Transportadora]]) -> 775 | H19: =COUNTIFS(tblPedidos[transportadora],tblTransportadora[[#This Row],[Transportadora]],tblPedidos[estado_operativo],"ENTREGADO") -> 416 | I19: =COUNTIFS(tblPedidos[transportadora],tblTransportadora[[#This Row],[Transportadora]],tblPedidos[estado_operativo],"DEVOLUCION") -> 45 | J19: =IFERROR(tblTransportadora[[#This Row],[Devolución]]/tblTransportadora[[#This Row],[Pedidos]],0) -> 0.058064516 | K19: =IFERROR(tblTransportadora[[#This Row],[Entregados]]/tblTransportadora[[#This Row],[Pedidos]],0) -> 0.53677419
B20: TRANSITO | C20: =IFERROR(COUNTIFS(tblPedidos[estado_operativo],B20),0) -> 92 | F20: VELOCES | G20: =COUNTIFS(tblPedidos[transportadora],tblTransportadora[[#This Row],[Transportadora]]) -> 26 | H20: =COUNTIFS(tblPedidos[transportadora],tblTransportadora[[#This Row],[Transportadora]],tblPedidos[estado_operativo],"ENTREGADO") -> 15 | I20: =COUNTIFS(tblPedidos[transportadora],tblTransportadora[[#This Row],[Transportadora]],tblPedidos[estado_operativo],"DEVOLUCION") -> 3 | J20: =IFERROR(tblTransportadora[[#This Row],[Devolución]]/tblTransportadora[[#This Row],[Pedidos]],0) -> 0.11538462 | K20: =IFERROR(tblTransportadora[[#This Row],[Entregados]]/tblTransportadora[[#This Row],[Pedidos]],0) -> 0.57692308
B21: DESTINO | C21: =IFERROR(COUNTIFS(tblPedidos[estado_operativo],B21),0) -> 16 | F21: COORDINADORA | G21: =COUNTIFS(tblPedidos[transportadora],tblTransportadora[[#This Row],[Transportadora]]) -> 0 | H21: =COUNTIFS(tblPedidos[transportadora],tblTransportadora[[#This Row],[Transportadora]],tblPedidos[estado_operativo],"ENTREGADO") -> 0 | I21: =COUNTIFS(tblPedidos[transportadora],tblTransportadora[[#This Row],[Transportadora]],tblPedidos[estado_operativo],"DEVOLUCION") -> 0 | J21: =IFERROR(tblTransportadora[[#This Row],[Devolución]]/tblTransportadora[[#This Row],[Pedidos]],0) -> 0 | K21: =IFERROR(tblTransportadora[[#This Row],[Entregados]]/tblTransportadora[[#This Row],[Pedidos]],0) -> 0
B22: REPARTO | C22: =IFERROR(COUNTIFS(tblPedidos[estado_operativo],B22),0) -> 31 | I22: =IF(H22="","",COUNTIF(#REF!,H22)) | J22: =IF(H22="","",COUNTIFS(#REF!,H22,#REF!,"ENTREGADO")) | K22: =IF(H22="","",COUNTIFS(#REF!,H22,#REF!,"DEVOLUCIÓN")) | L22: =IF(H22="","",IFERROR(K22/(J22+K22),0))
B23: ENTREGADO | C23: =IFERROR(COUNTIFS(tblPedidos[estado_operativo],B23),0) -> 567 | I23: =IF(H23="","",COUNTIF(#REF!,H23)) | J23: =IF(H23="","",COUNTIFS(#REF!,H23,#REF!,"ENTREGADO")) | K23: =IF(H23="","",COUNTIFS(#REF!,H23,#REF!,"DEVOLUCIÓN")) | L23: =IF(H23="","",IFERROR(K23/(J23+K23),0))
B24: DEVOLUCION | C24: =IFERROR(COUNTIFS(tblPedidos[estado_operativo],B24),0) -> 54 | I24: =IF(H24="","",COUNTIF(#REF!,H24)) | J24: =IF(H24="","",COUNTIFS(#REF!,H24,#REF!,"ENTREGADO")) | K24: =IF(H24="","",COUNTIFS(#REF!,H24,#REF!,"DEVOLUCIÓN")) | L24: =IF(H24="","",IFERROR(K24/(J24+K24),0))
B25: NOVEDAD | C25: =IFERROR(COUNTIFS(tblPedidos[estado_operativo],B25),0) -> 28 | I25: =IF(H25="","",COUNTIF(#REF!,H25)) | J25: =IF(H25="","",COUNTIFS(#REF!,H25,#REF!,"ENTREGADO")) | K25: =IF(H25="","",COUNTIFS(#REF!,H25,#REF!,"DEVOLUCIÓN")) | L25: =IF(H25="","",IFERROR(K25/(J25+K25),0))
B26: NOVEDAD SOLUCIONADA | C26: =IFERROR(COUNTIFS(tblPedidos[estado_operativo],B26),0) -> 5
B27: OFICINA | C27: =IFERROR(COUNTIFS(tblPedidos[estado_operativo],B27),0) -> 55
B28: OFICINA 1 | C28: =IFERROR(COUNTIFS(tblPedidos[estado_operativo],B28),0) -> 0
B29: CANCELADO | C29: =IFERROR(COUNTIFS(tblPedidos[estado_operativo],B29),0) -> 18
B30: SINIESTRO / EXTRAVIADO | C30: =IFERROR(COUNTIFS(tblPedidos[estado_operativo],B30),0) -> 0
B31: SIN MAPEAR | C31: =IFERROR(COUNTIFS(tblPedidos[estado_operativo],B31),0) -> 0
B33: PAUTA | C33: VALOR
B34: SEMANA 1
B35: SEMANA 2
B36: SEMANA 3
B37: SEMANA 4
B39: TOTAL | C39: =SUM(C34:C37) -> 0

Sheet Estados_Encontrados
A1: Estados encontrados en este export (para ayudarte a mapear)
A3: transportadora | B3: estatus_original | C3: ultimo_movimiento | D3: sugerido
A4: ENVIA | B4: PREPARADO PARA TRANSPORTADORA | C4: PREPARADO PARA TRANSPORTADORA | D4: ORIGEN
A5: INTERRAPIDISIMO | B5: PENDIENTE | C5: PENDIENTE | D5: PENDIENTE
A6: VELOCES | B6: GUIA_GENERADA | C6: GUIA_GENERADA | D6: ORIGEN
